Workbook

Sheet End-to-End Master Plan
A1: Module | B1: Task | C1: Component | D1: Dependency | E1: Estimates (Days) | F1: Resource | G1: Planned Start Date | H1: Planned End Date | I1: Milestone
A2: All Modules | B2: Unified UI Wireframe & UX Research | C2: UI | D2: Project Start | E2: 6 | F2: UX Designer | G2: 06-Jan-2026 | H2: =WORKDAY(G2,E2-1,Holidays!$A$2:$A$5) -> 46035
A3: All Modules | B3: KT Sessions to New Resources | C3: Cross-Team | D3: UX Baseline Approved | E3: 5 | F3: Leads (Backend/UI/QA) | G3: 19-Jan-2026 | H3: =WORKDAY(G3,E3-1,Holidays!$A$2:$A$5) -> 46045 | I3: KT Completed
A4: All Modules | B4: Wireframe Review & Sign-off | C4: UI | D4: Unified UI Wireframe & UX Research | E4: 4 | F4: UX + Stakeholders | G4: 12-Jan-2026 | H4: =WORKDAY(G4,E4-1,Holidays!$A$2:$A$5) -> 46037 | I4: UX Baseline Approved
A5: Module 1: API Connector Master | B5: System Analysis | C5: Backend | D5: Development Kickoff | E5: 3 | F5: Backend Architect | G5: 03-Feb-2026 | H5: =WORKDAY(G5,E5-1,Holidays!$A$2:$A$5) -> 46058
A6: Module 1: API Connector Master | B6: Connector Module Implementation | C6: Backend | D6: System Analysis | E6: 5 | F6: Backend Team | G6: 03-Feb-2026 | H6: =WORKDAY(G6,E6-1,Holidays!$A$2:$A$5) -> 46062
A7: Module 1: API Connector Master | B7: Token Logic Implementation | C7: Backend | D7: Connector Module Implementation | E7: 4 | F7: Backend Team | G7: 03-Feb-2026 | H7: =WORKDAY(G7,E7-1,Holidays!$A$2:$A$5) -> 46059
A8: Module 1: API Connector Master | B8: Connector Model & Token Logic | C8: Backend | D8: Development Kickoff | E8: 14 | F8: Backend Team | G8: 03-Feb-2026 | H8: =WORKDAY(G8,E8-1,Holidays!$A$2:$A$5) -> 46073
A9: Module 1: API Connector Master | B9: API Connector UI | C9: UI | D9: UX Baseline Approved | E9: 12 | F9: UI Team | G9: 03-Feb-2026 | H9: =WORKDAY(G9,E9-1,Holidays!$A$2:$A$5) -> 46071
A10: Module 1: API Connector Master | B10: QA Test Scenario & Data Preparation | C10: QA | D10: Connector Model & Token Logic | E10: 4 | F10: QA Team | G10: 03-Feb-2026 | H10: =WORKDAY(G10,E10-1,Holidays!$A$2:$A$5) -> 46059
A11: Module 1: API Connector Master | B11: QA Functional & Integration Testing | C11: QA | D11: API Connector UI | E11: 6 | F11: QA Team | G11: 03-Feb-2026 | H11: =WORKDAY(G11,E11-1,Holidays!$A$2:$A$5) -> 46063
A12: Module 1: API Connector Master | B12: Backend Bug Fixing | C12: Backend | D12: QA Functional Testing | E12: 3 | F12: Backend Team | G12: 03-Feb-2026 | H12: =WORKDAY(G12,E12-1,Holidays!$A$2:$A$5) -> 46058
A13: Module 1: API Connector Master | B13: UI Bug Fixing | C13: UI | D13: QA Functional Testing | E13: 2 | F13: UI Team | G13: 03-Feb-2026 | H13: =WORKDAY(G13,E13-1,Holidays!$A$2:$A$5) -> 46057
A14: Module 1: API Connector Master | B14: QA Bug Retest & Stabilization | C14: QA | D14: Backend Bug Fixing & UI Bug Fixing | E14: 2 | F14: QA Team | G14: 03-Feb-2026 | H14: =WORKDAY(G14,E14-1,Holidays!$A$2:$A$5) -> 46057 | I14: Module 2 Complete
A15: Module 2: DB Connector Master | B15: System Analysis | C15: Backend | D15: Development Kickoff | E15: 3 | F15: Backend Architect | G15: 01-Feb-2026 | H15: =WORKDAY(G15,E15-1,Holidays!$A$2:$A$5) -> 46056
A16: Module 2: DB Connector Master | B16: Connector Module Implementation | C16: Backend | D16: System Analysis | E16: 5 | F16: Backend Team | G16: 01-Feb-2026 | H16: =WORKDAY(G16,E16-1,Holidays!$A$2:$A$5) -> 46058
A17: Module 2: DB Connector Master | B17: Token Logic Implementation | C17: Backend | D17: Connector Module Implementation | E17: 4 | F17: Backend Team | G17: 01-Feb-2026 | H17: =WORKDAY(G17,E17-1,Holidays!$A$2:$A$5) -> 46057
A18: Module 2: DB Connector Master | B18: DB Connector Backend & Pooling | C18: Backend | D18: Development Kickoff | E18: 14 | F18: Backend Team | G18: 01-Feb-2026 | H18: =WORKDAY(G18,E18-1,Holidays!$A$2:$A$5) -> 46071
A19: Module 2: DB Connector Master | B19: DB Connector UI | C19: UI | D19: UX Baseline Approved | E19: 10 | F19: UI Team | G19: 15-Feb-2026 | H19: =WORKDAY(G19,E19-1,Holidays!$A$2:$A$5) -> 46079
A20: Module 2: DB Connector Master | B20: QA Test Case Design & Query Validation | C20: QA | D20: DB Connector Backend & Pooling | E20: 4 | F20: QA Team | G20: 15-Feb-2026 | H20: =WORKDAY(G20,E20-1,Holidays!$A$2:$A$5) -> 46071
A21: Module 2: DB Connector Master | B21: QA Functional & Data Accuracy Testing | C21: QA | D21: DB Connector UI | E21: 6 | F21: QA Team | G21: 21-Feb-2026 | H21: =WORKDAY(G21,E21-1,Holidays!$A$2:$A$5) -> 46080
A22: Module 2: DB Connector Master | B22: Backend Bug Fixing | C22: Backend | D22: QA Functional Testing | E22: 3 | F22: Backend Team | G22: 01-Mar-2026 | H22: =WORKDAY(G22,E22-1,Holidays!$A$2:$A$5) -> 46084
A23: Module 2: DB Connector Master | B23: UI Bug Fixing | C23: UI | D23: QA Functional Testing | E23: 2 | F23: UI Team | G23: 01-Mar-2026 | H23: =WORKDAY(G23,E23-1,Holidays!$A$2:$A$5) -> 46083
A24: Module 2: DB Connector Master | B24: QA Bug Retest & Regression | C24: QA | D24: Backend Bug Fixing & UI Bug Fixing | E24: 2 | F24: QA Team | G24: 01-Mar-2026 | H24: =WORKDAY(G24,E24-1,Holidays!$A$2:$A$5) -> 46083 | I24: Module 3 Complete
A25: Module 3: Test Case Management | B25: Test Case CRUD & Versioning APIs | C25: Backend | D25: Module 2 Complete | E25: 20 | F25: Backend Team | G25: 10-Feb-2026 | H25: =WORKDAY(G25,E25-1,Holidays!$A$2:$A$5) -> 46091
A26: Module 3: Test Case Management | B26: Test Case Management UI | C26: UI | D26: UX Baseline Approved | E26: 18 | F26: UI Team | G26: 20-Feb-2026 | H26: =WORKDAY(G26,E26-1,Holidays!$A$2:$A$5) -> 46099
A27: Module 3: Test Case Management | B27: QA Test Case Design & Rule Matrix | C27: QA | D27: Test Case CRUD & Versioning APIs | E27: 5 | F27: QA Team | G27: 05-Mar-2026 | H27: =WORKDAY(G27,E27-1,Holidays!$A$2:$A$5) -> 46092
A28: Module 3: Test Case Management | B28: QA Functional & UI Validation | C28: QA | D28: Test Case Management UI | E28: 7 | F28: QA Team | G28: 11-Mar-2026 | H28: =WORKDAY(G28,E28-1,Holidays!$A$2:$A$5) -> 46100
A29: Module 3: Test Case Management | B29: Backend Bug Fixing | C29: Backend | D29: QA Functional Testing | E29: 3 | F29: Backend Team | G29: 21-Mar-2026 | H29: =WORKDAY(G29,E29-1,Holidays!$A$2:$A$5) -> 46105
A30: Module 3: Test Case Management | B30: UI Bug Fixing | C30: UI | D30: QA Functional Testing | E30: 2 | F30: UI Team | G30: 21-Mar-2026 | H30: =WORKDAY(G30,E30-1,Holidays!$A$2:$A$5) -> 46104
A31: Module 3: Test Case Management | B31: QA Bug Retest & Version Validation | C31: QA | D31: Backend Bug Fixing & UI Bug Fixing | E31: 3 | F31: QA Team | G31: 21-Mar-2026 | H31: =WORKDAY(G31,E31-1,Holidays!$A$2:$A$5) -> 46105 | I31: Test Case Creation Ready
A32: Module 4: Bulk Test Case Import | B32: Import Template Design (CSV/Excel) | C32: Backend | D32: Test Case Creation Ready | E32: 5 | F32: Backend + QA | G32: 01-Apr-2026 | H32: =WORKDAY(G32,E32-1,Holidays!$A$2:$A$5) -> 46119 | I32: Template Finalized
A33: Module 4: Bulk Test Case Import | B33: Bulk Import Parser & Validation | C33: Backend | D33: Import Template Design (CSV/Excel) | E33: 10 | F33: Backend Team | G33: 06-Apr-2026 | H33: =WORKDAY(G33,E33-1,Holidays!$A$2:$A$5) -> 46129
A34: Module 4: Bulk Test Case Import | B34: Bulk Import UI | C34: UI | D34: UX Baseline Approved | E34: 8 | F34: UI Team | G34: 05-Apr-2026 | H34: =WORKDAY(G34,E34-1,Holidays!$A$2:$A$5) -> 46126
A35: Module 4: Bulk Test Case Import | B35: QA Template Review & Test Data Prep | C35: QA | D35: Import Template Design (CSV/Excel) | E35: 3 | F35: QA Team | G35: 03-Apr-2026 | H35: =WORKDAY(G35,E35-1,Holidays!$A$2:$A$5) -> 46119
A36: Module 4: Bulk Test Case Import | B36: QA Bulk Import Functional Testing | C36: QA | D36: Bulk Import Parser & Validation | E36: 4 | F36: QA Team | G36: 19-Apr-2026 | H36: =WORKDAY(G36,E36-1,Holidays!$A$2:$A$5) -> 46134
A37: Module 4: Bulk Test Case Import | B37: Backend Bug Fixing | C37: Backend | D37: QA Functional Testing | E37: 3 | F37: Backend Team | G37: 25-Apr-2026 | H37: =WORKDAY(G37,E37-1,Holidays!$A$2:$A$5) -> 46140
A38: Module 4: Bulk Test Case Import | B38: UI Bug Fixing | C38: UI | D38: QA Functional Testing | E38: 2 | F38: UI Team | G38: 25-Apr-2026 | H38: =WORKDAY(G38,E38-1,Holidays!$A$2:$A$5) -> 46139
A39: Module 4: Bulk Test Case Import | B39: QA Bug Retest & Partial Success Validation | C39: QA | D39: Backend Bug Fixing & UI Bug Fixing | E39: 2 | F39: QA Team | G39: 25-Apr-2026 | H39: =WORKDAY(G39,E39-1,Holidays!$A$2:$A$5) -> 46139 | I39: Bulk Import Ready
A40: Module 5: Test Execution Engine | B40: Execution Engine Core Services | C40: Backend | D40: Module 4 Complete | E40: 20 | F40: Backend Team | G40: 01-Mar-2026 | H40: =WORKDAY(G40,E40-1,Holidays!$A$2:$A$5) -> 46108
...

Sheet Holidays
A1: Holiday Date
A2: 01-Jan-2026
A3: 26-Jan-2026
A4: 04-Mar-2026
A5: 01-May-2026
